Workbook

Sheet Dashboard
A1: Active Scenario
A2: Downside
A5: TTM Revenue | E5: TTM EBITDA | I5: TTM EBITDA Margin
N9: EBITDA Margins
A11: Trailing 12 months
A12: Latest Month Revenue | E12: Latest Gross Margin | I12: Latest CAC
A13: =Analysis!$B$8 -> 8640981.1 | E13: =Analysis!$B$9 -> 0.35339721 | I13: =Analysis!$B$11 -> 510075.03
N14: EBITDA
A15: =Analysis!$B$7 -> 46081
N18: Revenue
N29: Matthew Tembo 2026 Dashboards

Sheet Analysis
A1: Analysis Hub — KPI calculations, mix breakdowns, and insight drivers
A4: Core KPIs (based on latest actuals and trailing 12 months)
A6: KPI | B6: Value | D6: TTM Revenue Mix | K6: TTM Start | L6: =INDEX(Model_PnL!$A$7:$A$42,MATCH($B$7,Model_PnL!$A$7:$A$42,0)-11) -> 45747
A7: Latest Actual Month | B7: =MAX(Model_PnL!$A$7:$A$42) -> 46081 | D7: By Region | F7: By Channel | H7: Share | K7: TTM End | L7: =$B$7 -> 46081
A8: Latest Month Revenue | B8: =INDEX(Model_PnL!$C$7:$C$42,MATCH($B$7,Model_PnL!$A$7:$A$42,0)) -> 8640981.1 | D8: Region | E8: Revenue | F8: Channel | G8: Revenue | H8: Share
A9: Latest Gross Margin | B9: =INDEX(Model_PnL!$F$7:$F$42,MATCH($B$7,Model_PnL!$A$7:$A$42,0)) -> 0.35339721 | D9: North America | E9: 44295376 | F9: Online DTC | G9: 65593133 | H9: =IFERROR(G9/SUM($G$9:$G$11),0) -> 0.585789
A10: Latest EBITDA Margin | B10: =INDEX(Model_PnL!$L$7:$L$42,MATCH($B$7,Model_PnL!$A$7:$A$42,0)) -> 0.059029758 | D10: Europe | E10: 34350416 | F10: Marketplace | G10: 26457807 | H10: =IFERROR(G10/SUM($G$9:$G$11),0) -> 0.23628529
A11: Latest CAC | B11: =INDEX(Model_PnL!$O$7:$O$42,MATCH($B$7,Model_PnL!$A$7:$A$42,0)) -> 510075.03 | D11: APAC | E11: 23616231 | F11: Wholesale | G11: 19923051 | H11: =IFERROR(G11/SUM($G$9:$G$11),0) -> 0.17792571
A12: TTM Revenue | B12: =SUM(Model_PnL!$C$31:$C$42) -> 1.1197399e+08 | D12: LATAM | E12: 9711967.9
A13: TTM EBITDA | B13: =SUM(Model_PnL!$K$31:$K$42) -> 8722421.7 | D13: Growth & Efficiency Signals
A14: TTM EBITDA Margin | B14: =IFERROR(SUM(Model_PnL!$K$31:$K$42)/SUM(Model_PnL!$C$31:$C$42),0) -> 0.077896855 | D14: TTM Revenue Growth vs Prior 12m | E14: =IFERROR((SUM(Model_PnL!$C$31:$C$42)-SUM(Model_PnL!$C$19:$C$30))/SUM(Model_PnL!$C$19:$C$30),0) -> 0.20349746
A15: Next 12m Forecast Revenue | B15: =SUM('Forecast Engine'!$E$11:$E$22) -> 1.1789932e+08 | D15: TTM Gross Margin | E15: =IFERROR(SUM(Model_PnL!$E$31:$E$42)/SUM(Model_PnL!$C$31:$C$42),0) -> 0.3517746
A16: Next 12m Forecast EBITDA | B16: =SUM('Forecast Engine'!$J$11:$J$22) -> -2844629.5 | D16: TTM Marketing % of Revenue | E16: =IFERROR(SUM(Model_PnL!$G$31:$G$42)/SUM(Model_PnL!$C$31:$C$42),0) -> 0.048045094
A17: Forecast EBITDA Margin | B17: =IFERROR(SUM('Forecast Engine'!$J$11:$J$22)/SUM('Forecast Engine'!$E$11:$E$22),0) -> -0.024127616 | D17: TTM CAC Trend (last 6m vs prior 6m) | E17: =IFERROR((AVERAGE(Model_PnL!$O$37:$O$42)-AVERAGE(Model_PnL!$O$31:$O$36))/AVERAGE(Model_PnL!$O$31:$O$36),0) -> 0.24151619

Sheet Inputs
A1: Assumptions & Scenarios
G3: guide
A4: Scenario | B4: =Dashboard!A2 -> Downside | C4: Scenario # | D4: Model Currency | E4: USD | G4: Blue text = user inputs Green text = links Purple = logic Black = formulas
B5: Select scenario in B4 | C5: =MATCH($B$4,$A$7:$A$9,0) -> 3
A6: Scenario List
A7: Base
A8: Upside
A9: Downside
A10: Key levers (edit blue cells) - used by Forecast and Dashboard
A11: Assumption | B11: Base | C11: Upside | D11: Downside | E11: Active
A12: Revenue uplift vs baseline (next 12m) | B12: 0 | C12: 0.07 | D12: -0.06 | E12: =CHOOSE($C$5,B12,C12,D12) -> -0.06
A13: Gross margin shift (bps) | B13: 0 | C13: 80 | D13: -120 | E13: =CHOOSE($C$5,B13,C13,D13) -> -120
A14: Marketing spend (% of revenue) | B14: 0.12 | C14: 0.11 | D14: 0.14 | E14: =CHOOSE($C$5,B14,C14,D14) -> 0.14
A15: Operating expense growth (annual) | B15: 0.06 | C15: 0.04 | D15: 0.09 | E15: =CHOOSE($C$5,B15,C15,D15) -> 0.09
A16: Price change (annual) | B16: 0.03 | C16: 0.05 | D16: 0.01 | E16: =CHOOSE($C$5,B16,C16,D16) -> 0.01
A17: Unit volume change (annual) | B17: 0.07 | C17: 0.1 | D17: 0.03 | E17: =CHOOSE($C$5,B17,C17,D17) -> 0.03

Sheet Model_PnL
A1: Monthly P&L, KPIs, and Trend Metrics
A4: Actuals: Mar-2023 to Feb-2026 | Forecast: Mar-2026 to Feb-2027 (scenario-driven)
A6: Month | B6: t | C6: Net Revenue | D6: COGS | E6: Gross Profit | F6: GM % | G6: Marketing Spend | H6: Payroll | I6: Other Opex | J6: Total Opex | K6: EBITDA | L6: EBITDA % | M6: Actual Net Revenue | N6: Forecast Net Revenue | O6: Actual EBITDA | P6: Forecast EBITDA | Q6: Revenue (3M Rolling)
A7: 45016 | B7: 1 | C7: =Agg_Monthly!$B$2 -> 6111106.7 | D7: =Agg_Monthly!$C$2 -> 4028660.1 | E7: =C7-D7 -> 2082446.6 | F7: =IFERROR(E7/C7,0) -> 0.34076423 | G7: =Agg_Monthly!$D$2 -> 287718.37 | H7: =Agg_Opex!$B$2 -> 794929.83 | I7: =Agg_Opex!$C$2 -> 982398 | J7: =G7+H7+I7 -> 2065046.2 | K7: =E7-G7-H7-I7 -> 17400.389 | L7: =IFERROR(K7/C7,0) -> 0.0028473384 | M7: =IF(ROW()<43,C7,NA()) -> 6111106.7 | N7: =IF(ROW()>=43,C7,NA()) -> #N/A | O7: =IF(ROW()<43,K7,NA()) -> 17400.389 | P7: =IF(ROW()>=43,K7,NA()) -> #N/A | Q7: =IF($B7>2,SUM(C5:C7),"")
A8: 45046 | B8: 2 | C8: =Agg_Monthly!$B$3 -> 6112814.3 | D8: =Agg_Monthly!$C$3 -> 4049039.1 | E8: =C8-D8 -> 2063775.1 | F8: =IFERROR(E8/C8,0) -> 0.33761457 | G8: =Agg_Monthly!$D$3 -> 323051.33 | H8: =Agg_Opex!$B$3 -> 818939.33 | I8: =Agg_Opex!$C$3 -> 1011498 | J8: =G8+H8+I8 -> 2153488.7 | K8: =E8-G8-H8-I8 -> -89713.519 | L8: =IFERROR(K8/C8,0) -> -0.014676304 | M8: =IF(ROW()<43,C8,NA()) -> 6112814.3 | N8: =IF(ROW()>=43,C8,NA()) -> #N/A | O8: =IF(ROW()<43,K8,NA()) -> -89713.519 | P8: =IF(ROW()>=43,K8,NA()) -> #N/A | Q8: =IF($B8>2,SUM(C6:C8),"")
A9: 45077 | B9: 3 | C9: =Agg_Monthly!$B$4 -> 6464674.9 | D9: =Agg_Monthly!$C$4 -> 4220475.6 | E9: =C9-D9 -> 2244199.3 | F9: =IFERROR(E9/C9,0) -> 0.34714805 | G9: =Agg_Monthly!$D$4 -> 331177.31 | H9: =Agg_Opex!$B$4 -> 824754.5 | I9: =Agg_Opex!$C$4 -> 950921 | J9: =G9+H9+I9 -> 2106852.8 | K9: =E9-G9-H9-I9 -> 137346.48 | L9: =IFERROR(K9/C9,0) -> 0.02124569 | M9: =IF(ROW()<43,C9,NA()) -> 6464674.9 | N9: =IF(ROW()>=43,C9,NA()) -> #N/A | O9: =IF(ROW()<43,K9,NA()) -> 137346.48 | P9: =IF(ROW()>=43,K9,NA()) -> #N/A | Q9: =IF($B9>2,SUM(C7:C9),"") -> 18688596
A10: 45107 | B10: 4 | C10: =Agg_Monthly!$B$5 -> 6892942.5 | D10: =Agg_Monthly!$C$5 -> 4524380 | E10: =C10-D10 -> 2368562.6 | F10: =IFERROR(E10/C10,0) -> 0.3436214 | G10: =Agg_Monthly!$D$5 -> 390841.65 | H10: =Agg_Opex!$B$5 -> 800499.17 | I10: =Agg_Opex!$C$5 -> 991353 | J10: =G10+H10+I10 -> 2182693.8 | K10: =E10-G10-H10-I10 -> 185868.75 | L10: =IFERROR(K10/C10,0) -> 0.02696508 | M10: =IF(ROW()<43,C10,NA()) -> 6892942.5 | N10: =IF(ROW()>=43,C10,NA()) -> #N/A | O10: =IF(ROW()<43,K10,NA()) -> 185868.75 | P10: =IF(ROW()>=43,K10,NA()) -> #N/A | Q10: =IF($B10>2,SUM(C8:C10),"") -> 19470432
A11: 45138 | B11: 5 | C11: =Agg_Monthly!$B$6 -> 6958622.9 | D11: =Agg_Monthly!$C$6 -> 4623110.5 | E11: =C11-D11 -> 2335512.4 | F11: =IFERROR(E11/C11,0) -> 0.33562853 | G11: =Agg_Monthly!$D$6 -> 401729.77 | H11: =Agg_Opex!$B$6 -> 824750.67 | I11: =Agg_Opex!$C$6 -> 978587 | J11: =G11+H11+I11 -> 2205067.4 | K11: =E11-G11-H11-I11 -> 130444.93 | L11: =IFERROR(K11/C11,0) -> 0.018745797 | M11: =IF(ROW()<43,C11,NA()) -> 6958622.9 | N11: =IF(ROW()>=43,C11,NA()) -> #N/A | O11: =IF(ROW()<43,K11,NA()) -> 130444.93 | P11: =IF(ROW()>=43,K11,NA()) -> #N/A | Q11: =IF($B11>2,SUM(C9:C11),"") -> 20316240
A12: 45169 | B12: 6 | C12: =Agg_Monthly!$B$7 -> 6349906.8 | D12: =Agg_Monthly!$C$7 -> 4153524.3 | E12: =C12-D12 -> 2196382.5 | F12: =IFERROR(E12/C12,0) -> 0.34589209 | G12: =Agg_Monthly!$D$7 -> 371589.65 | H12: =Agg_Opex!$B$7 -> 837845.75 | I12: =Agg_Opex!$C$7 -> 974751 | J12: =G12+H12+I12 -> 2184186.4 | K12: =E12-G12-H12-I12 -> 12196.105 | L12: =IFERROR(K12/C12,0) -> 0.0019206746 | M12: =IF(ROW()<43,C12,NA()) -> 6349906.8 | N12: =IF(ROW()>=43,C12,NA()) -> #N/A | O12: =IF(ROW()<43,K12,NA()) -> 12196.105 | P12: =IF(ROW()>=43,K12,NA()) -> #N/A | Q12: =IF($B12>2,SUM(C10:C12),"") -> 20201472
A13: 45199 | B13: 7 | C13: =Agg_Monthly!$B$8 -> 6791502.7 | D13: =Agg_Monthly!$C$8 -> 4491153.4 | E13: =C13-D13 -> 2300349.3 | F13: =IFERROR(E13/C13,0) -> 0.33870991 | G13: =Agg_Monthly!$D$8 -> 353431.32 | H13: =Agg_Opex!$B$8 -> 845206.75 | I13: =Agg_Opex!$C$8 -> 1099285 | J13: =G13+H13+I13 -> 2297923.1 | K13: =E13-G13-H13-I13 -> 2426.2307 | L13: =IFERROR(K13/C13,0) -> 0.00035724504 | M13: =IF(ROW()<43,C13,NA()) -> 6791502.7 | N13: =IF(ROW()>=43,C13,NA()) -> #N/A | O13: =IF(ROW()<43,K13,NA()) -> 2426.2307 | P13: =IF(ROW()>=43,K13,NA()) -> #N/A | Q13: =IF($B13>2,SUM(C11:C13),"") -> 20100032
A14: 45230 | B14: 8 | C14: =Agg_Monthly!$B$9 -> 6747149 | D14: =Agg_Monthly!$C$9 -> 4380190.7 | E14: =C14-D14 -> 2366958.3 | F14: =IFERROR(E14/C14,0) -> 0.35080866 | G14: =Agg_Monthly!$D$9 -> 356364.25 | H14: =Agg_Opex!$B$9 -> 830136.33 | I14: =Agg_Opex!$C$9 -> 1013925 | J14: =G14+H14+I14 -> 2200425.6 | K14: =E14-G14-H14-I14 -> 166532.71 | L14: =IFERROR(K14/C14,0) -> 0.024681938 | M14: =IF(ROW()<43,C14,NA()) -> 6747149 | N14: =IF(ROW()>=43,C14,NA()) -> #N/A | O14: =IF(ROW()<43,K14,NA()) -> 166532.71 | P14: =IF(ROW()>=43,K14,NA()) -> #N/A | Q14: =IF($B14>2,SUM(C12:C14),"") -> 19888559
A15: 45260 | B15: 9 | C15: =Agg_Monthly!$B$10 -> 7870188.9 | D15: =Agg_Monthly!$C$10 -> 5294709.9 | E15: =C15-D15 -> 2575479 | F15: =IFERROR(E15/C15,0) -> 0.32724488 | G15: =Agg_Monthly!$D$10 -> 412347.22 | H15: =Agg_Opex!$B$10 -> 867556.83 | I15: =Agg_Opex!$C$10 -> 1158992 | J15: =G15+H15+I15 -> 2438896.1 | K15: =E15-G15-H15-I15 -> 136582.95 | L15: =IFERROR(K15/C15,0) -> 0.017354469 | M15: =IF(ROW()<43,C15,NA()) -> 7870188.9 | N15: =IF(ROW()>=43,C15,NA()) -> #N/A | O15: =IF(ROW()<43,K15,NA()) -> 136582.95 | P15: =IF(ROW()>=43,K15,NA()) -> #N/A | Q15: =IF($B15>2,SUM(C13:C15),"") -> 21408841
A16: 45291 | B16: 10 | C16: =Agg_Monthly!$B$11 -> 8601676.2 | D16: =Agg_Monthly!$C$11 -> 5883293.6 | E16: =C16-D16 -> 2718382.6 | F16: =IFERROR(E16/C16,0) -> 0.3160294 | G16: =Agg_Monthly!$D$11 -> 457007.23 | H16: =Agg_Opex!$B$11 -> 855319.33 | I16: =Agg_Opex!$C$11 -> 1124583 | J16: =G16+H16+I16 -> 2436909.6 | K16: =E16-G16-H16-I16 -> 281473.04 | L16: =IFERROR(K16/C16,0) -> 0.032723046 | M16: =IF(ROW()<43,C16,NA()) -> 8601676.2 | N16: =IF(ROW()>=43,C16,NA()) -> #N/A | O16: =IF(ROW()<43,K16,NA()) -> 281473.04 | P16: =IF(ROW()>=43,K16,NA()) -> #N/A | Q16: =IF($B16>2,SUM(C14:C16),"") -> 23219014
A17: 45322 | B17: 11 | C17: =Agg_Monthly!$B$12 -> 5938555.9 | D17: =Agg_Monthly!$C$12 -> 3882425.4 | E17: =C17-D17 -> 2056130.5 | F17: =IFERROR(E17/C17,0) -> 0.34623409 | G17: =Agg_Monthly!$D$12 -> 265644.7 | H17: =Agg_Opex!$B$12 -> 870086.92 | I17: =Agg_Opex!$C$12 -> 1003694 | J17: =G17+H17+I17 -> 2139425.6 | K17: =E17-G17-H17-I17 -> -83295.12 | L17: =IFERROR(K17/C17,0) -> -0.014026158 | M17: =IF(ROW()<43,C17,NA()) -> 5938555.9 | N17: =IF(ROW()>=43,C17,NA()) -> #N/A | O17: =IF(ROW()<43,K17,NA()) -> -83295.12 | P17: =IF(ROW()>=43,K17,NA()) -> #N/A | Q17: =IF($B17>2,SUM(C15:C17),"") -> 22410421
A18: 45351 | B18: 12 | C18: =Agg_Monthly!$B$13 -> 7017084.1 | D18: =Agg_Monthly!$C$13 -> 4533151.7 | E18: =C18-D18 -> 2483932.4 | F18: =IFERROR(E18/C18,0) -> 0.35398356 | G18: =Agg_Monthly!$D$13 -> 371175.7 | H18: =Agg_Opex!$B$13 -> 887942.67 | I18: =Agg_Opex!$C$13 -> 990879 | J18: =G18+H18+I18 -> 2249997.4 | K18: =E18-G18-H18-I18 -> 233935.07 | L18: =IFERROR(K18/C18,0) -> 0.033337932 | M18: =IF(ROW()<43,C18,NA()) -> 7017084.1 | N18: =IF(ROW()>=43,C18,NA()) -> #N/A | O18: =IF(ROW()<43,K18,NA()) -> 233935.07 | P18: =IF(ROW()>=43,K18,NA()) -> #N/A | Q18: =IF($B18>2,SUM(C16:C18),"") -> 21557316
A19: 45382 | B19: 13 | C19: =Agg_Monthly!$B$14 -> 6758152.6 | D19: =Agg_Monthly!$C$14 -> 4375280.1 | E19: =C19-D19 -> 2382872.5 | F19: =IFERROR(E19/C19,0) -> 0.35259228 | G19: =Agg_Monthly!$D$14 -> 341012.76 | H19: =Agg_Opex!$B$14 -> 855414.33 | I19: =Agg_Opex!$C$14 -> 1006466 | J19: =G19+H19+I19 -> 2202893.1 | K19: =E19-G19-H19-I19 -> 179979.36 | L19: =IFERROR(K19/C19,0) -> 0.026631444 | M19: =IF(ROW()<43,C19,NA()) -> 6758152.6 | N19: =IF(ROW()>=43,C19,NA()) -> #N/A | O19: =IF(ROW()<43,K19,NA()) -> 179979.36 | P19: =IF(ROW()>=43,K19,NA()) -> #N/A | Q19: =IF($B19>2,SUM(C17:C19),"") -> 19713793
A20: 45412 | B20: 14 | C20: =Agg_Monthly!$B$15 -> 7319175.5 | D20: =Agg_Monthly!$C$15 -> 4844045.3 | E20: =C20-D20 -> 2475130.2 | F20: =IFERROR(E20/C20,0) -> 0.33817063 | G20: =Agg_Monthly!$D$15 -> 390632.54 | H20: =Agg_Opex!$B$15 -> 914548 | I20: =Agg_Opex!$C$15 -> 996515 | J20: =G20+H20+I20 -> 2301695.5 | K20: =E20-G20-H20-I20 -> 173434.69 | L20: =IFERROR(K20/C20,0) -> 0.023695933 | M20: =IF(ROW()<43,C20,NA()) -> 7319175.5 | N20: =IF(ROW()>=43,C20,NA()) -> #N/A | O20: =IF(ROW()<43,K20,NA()) -> 173434.69 | P20: =IF(ROW()>=43,K20,NA()) -> #N/A | Q20: =IF($B20>2,SUM(C18:C20),"") -> 21094412
A21: 45443 | B21: 15 | C21: =Agg_Monthly!$B$16 -> 8092188 | D21: =Agg_Monthly!$C$16 -> 5251625 | E21: =C21-D21 -> 2840563 | F21: =IFERROR(E21/C21,0) -> 0.35102534 | G21: =Agg_Monthly!$D$16 -> 360129.19 | H21: =Agg_Opex!$B$16 -> 902724.58 | I21: =Agg_Opex!$C$16 -> 940527 | J21: =G21+H21+I21 -> 2203380.8 | K21: =E21-G21-H21-I21 -> 637182.25 | L21: =IFERROR(K21/C21,0) -> 0.078740416 | M21: =IF(ROW()<43,C21,NA()) -> 8092188 | N21: =IF(ROW()>=43,C21,NA()) -> #N/A | O21: =IF(ROW()<43,K21,NA()) -> 637182.25 | P21: =IF(ROW()>=43,K21,NA()) -> #N/A | Q21: =IF($B21>2,SUM(C19:C21),"") -> 22169516
A22: 45473 | B22: 16 | C22: =Agg_Monthly!$B$17 -> 6996480.3 | D22: =Agg_Monthly!$C$17 -> 4531021.7 | E22: =C22-D22 -> 2465458.6 | F22: =IFERROR(E22/C22,0) -> 0.35238556 | G22: =Agg_Monthly!$D$17 -> 360719.94 | H22: =Agg_Opex!$B$17 -> 908719.17 | I22: =Agg_Opex!$C$17 -> 1065511 | J22: =G22+H22+I22 -> 2334950.1 | K22: =E22-G22-H22-I22 -> 130508.52 | L22: =IFERROR(K22/C22,0) -> 0.018653454 | M22: =IF(ROW()<43,C22,NA()) -> 6996480.3 | N22: =IF(ROW()>=43,C22,NA()) -> #N/A | O22: =IF(ROW()<43,K22,NA()) -> 130508.52 | P22: =IF(ROW()>=43,K22,NA()) -> #N/A | Q22: =IF($B22>2,SUM(C20:C22),"") -> 22407844
A23: 45504 | B23: 17 | C23: =Agg_Monthly!$B$18 -> 8179206.5 | D23: =Agg_Monthly!$C$18 -> 5234847.2 | E23: =C23-D23 -> 2944359.4 | F23: =IFERROR(E23/C23,0) -> 0.35998105 | G23: =Agg_Monthly!$D$18 -> 402358.3 | H23: =Agg_Opex!$B$18 -> 919576.67 | I23: =Agg_Opex!$C$18 -> 1043555 | J23: =G23+H23+I23 -> 2365490 | K23: =E23-G23-H23-I23 -> 578869.4 | L23: =IFERROR(K23/C23,0) -> 0.070773296 | M23: =IF(ROW()<43,C23,NA()) -> 8179206.5 | N23: =IF(ROW()>=43,C23,NA()) -> #N/A | O23: =IF(ROW()<43,K23,NA()) -> 578869.4 | P23: =IF(ROW()>=43,K23,NA()) -> #N/A | Q23: =IF($B23>2,SUM(C21:C23),"") -> 23267875
A24: 45535 | B24: 18 | C24: =Agg_Monthly!$B$19 -> 7645711 | D24: =Agg_Monthly!$C$19 -> 4902229.4 | E24: =C24-D24 -> 2743481.5 | F24: =IFERROR(E24/C24,0) -> 0.35882622 | G24: =Agg_Monthly!$D$19 -> 385680.57 | H24: =Agg_Opex!$B$19 -> 951645.75 | I24: =Agg_Opex!$C$19 -> 1012041 | J24: =G24+H24+I24 -> 2349367.3 | K24: =E24-G24-H24-I24 -> 394114.22 | L24: =IFERROR(K24/C24,0) -> 0.051547099 | M24: =IF(ROW()<43,C24,NA()) -> 7645711 | N24: =IF(ROW()>=43,C24,NA()) -> #N/A | O24: =IF(ROW()<43,K24,NA()) -> 394114.22 | P24: =IF(ROW()>=43,K24,NA()) -> #N/A | Q24: =IF($B24>2,SUM(C22:C24),"") -> 22821398
A25: 45565 | B25: 19 | C25: =Agg_Monthly!$B$20 -> 7961548.7 | D25: =Agg_Monthly!$C$20 -> 5115971 | E25: =C25-D25 -> 2845577.7 | F25: =IFERROR(E25/C25,0) -> 0.3574151 | G25: =Agg_Monthly!$D$20 -> 406189.59 | H25: =Agg_Opex!$B$20 -> 954588 | I25: =Agg_Opex!$C$20 -> 1079230 | J25: =G25+H25+I25 -> 2440007.6 | K25: =E25-G25-H25-I25 -> 405570.15 | L25: =IFERROR(K25/C25,0) -> 0.050941112 | M25: =IF(ROW()<43,C25,NA()) -> 7961548.7 | N25: =IF(ROW()>=43,C25,NA()) -> #N/A | O25: =IF(ROW()<43,K25,NA()) -> 405570.15 | P25: =IF(ROW()>=43,K25,NA()) -> #N/A | Q25: =IF($B25>2,SUM(C23:C25),"") -> 23786466
A26: 45596 | B26: 20 | C26: =Agg_Monthly!$B$21 -> 9093569.9 | D26: =Agg_Monthly!$C$21 -> 5920936.6 | E26: =C26-D26 -> 3172633.3 | F26: =IFERROR(E26/C26,0) -> 0.34888755 | G26: =Agg_Monthly!$D$21 -> 474895.35 | H26: =Agg_Opex!$B$21 -> 910068.92 | I26: =Agg_Opex!$C$21 -> 1126311 | J26: =G26+H26+I26 -> 2511275.3 | K26: =E26-G26-H26-I26 -> 661358.08 | L26: =IFERROR(K26/C26,0) -> 0.072728101 | M26: =IF(ROW()<43,C26,NA()) -> 9093569.9 | N26: =IF(ROW()>=43,C26,NA()) -> #N/A | O26: =IF(ROW()<43,K26,NA()) -> 661358.08 | P26: =IF(ROW()>=43,K26,NA()) -> #N/A | Q26: =IF($B26>2,SUM(C24:C26),"") -> 24700830
A27: 45626 | B27: 21 | C27: =Agg_Monthly!$B$22 -> 8334125.6 | D27: =Agg_Monthly!$C$22 -> 5644645.2 | E27: =C27-D27 -> 2689480.4 | F27: =IFERROR(E27/C27,0) -> 0.32270696 | G27: =Agg_Monthly!$D$22 -> 377657.36 | H27: =Agg_Opex!$B$22 -> 936287 | I27: =Agg_Opex!$C$22 -> 1207900 | J27: =G27+H27+I27 -> 2521844.4 | K27: =E27-G27-H27-I27 -> 167636.01 | L27: =IFERROR(K27/C27,0) -> 0.020114409 | M27: =IF(ROW()<43,C27,NA()) -> 8334125.6 | N27: =IF(ROW()>=43,C27,NA()) -> #N/A | O27: =IF(ROW()<43,K27,NA()) -> 167636.01 | P27: =IF(ROW()>=43,K27,NA()) -> #N/A | Q27: =IF($B27>2,SUM(C25:C27),"") -> 25389244
A28: 45657 | B28: 22 | C28: =Agg_Monthly!$B$23 -> 9565478.7 | D28: =Agg_Monthly!$C$23 -> 6413665.1 | E28: =C28-D28 -> 3151813.6 | F28: =IFERROR(E28/C28,0) -> 0.32949878 | G28: =Agg_Monthly!$D$23 -> 455713.01 | H28: =Agg_Opex!$B$23 -> 960952.5 | I28: =Agg_Opex!$C$23 -> 1200486 | J28: =G28+H28+I28 -> 2617151.5 | K28: =E28-G28-H28-I28 -> 534662.05 | L28: =IFERROR(K28/C28,0) -> 0.05589496 | M28: =IF(ROW()<43,C28,NA()) -> 9565478.7 | N28: =IF(ROW()>=43,C28,NA()) -> #N/A | O28: =IF(ROW()<43,K28,NA()) -> 534662.05 | P28: =IF(ROW()>=43,K28,NA()) -> #N/A | Q28: =IF($B28>2,SUM(C26:C28),"") -> 26993174
A29: 45688 | B29: 23 | C29: =Agg_Monthly!$B$24 -> 5971233.7 | D29: =Agg_Monthly!$C$24 -> 3909061.5 | E29: =C29-D29 -> 2062172.2 | F29: =IFERROR(E29/C29,0) -> 0.34535111 | G29: =Agg_Monthly!$D$24 -> 274150.31 | H29: =Agg_Opex!$B$24 -> 945090.92 | I29: =Agg_Opex!$C$24 -> 1127471 | J29: =G29+H29+I29 -> 2346712.2 | K29: =E29-G29-H29-I29 -> -284540.05 | L29: =IFERROR(K29/C29,0) -> -0.047651803 | M29: =IF(ROW()<43,C29,NA()) -> 5971233.7 | N29: =IF(ROW()>=43,C29,NA()) -> #N/A | O29: =IF(ROW()<43,K29,NA()) -> -284540.05 | P29: =IF(ROW()>=43,K29,NA()) -> #N/A | Q29: =IF($B29>2,SUM(C27:C29),"") -> 23870838
A30: 45716 | B30: 24 | C30: =Agg_Monthly!$B$25 -> 7123617.5 | D30: =Agg_Monthly!$C$25 -> 4575249.7 | E30: =C30-D30 -> 2548367.8 | F30: =IFERROR(E30/C30,0) -> 0.35773506 | G30: =Agg_Monthly!$D$25 -> 393038.81 | H30: =Agg_Opex!$B$25 -> 953142.25 | I30: =Agg_Opex!$C$25 -> 1098700 | J30: =G30+H30+I30 -> 2444881.1 | K30: =E30-G30-H30-I30 -> 103486.7 | L30: =IFERROR(K30/C30,0) -> 0.014527268 | M30: =IF(ROW()<43,C30,NA()) -> 7123617.5 | N30: =IF(ROW()>=43,C30,NA()) -> #N/A | O30: =IF(ROW()<43,K30,NA()) -> 103486.7 | P30: =IF(ROW()>=43,K30,NA()) -> #N/A | Q30: =IF($B30>2,SUM(C28:C30),"") -> 22660330
A31: 45747 | B31: 25 | C31: =Agg_Monthly!$B$26 -> 8562748.5 | D31: =Agg_Monthly!$C$26 -> 5511461.5 | E31: =C31-D31 -> 3051287.1 | F31: =IFERROR(E31/C31,0) -> 0.35634435 | G31: =Agg_Monthly!$D$26 -> 407763.73 | H31: =Agg_Opex!$B$26 -> 974990.83 | I31: =Agg_Opex!$C$26 -> 1121837 | J31: =G31+H31+I31 -> 2504591.6 | K31: =E31-G31-H31-I31 -> 546695.5 | L31: =IFERROR(K31/C31,0) -> 0.063845796 | M31: =IF(ROW()<43,C31,NA()) -> 8562748.5 | N31: =IF(ROW()>=43,C31,NA()) -> #N/A | O31: =IF(ROW()<43,K31,NA()) -> 546695.5 | P31: =IF(ROW()>=43,K31,NA()) -> #N/A | Q31: =IF($B31>2,SUM(C29:C31),"") -> 21657600
A32: 45777 | B32: 26 | C32: =Agg_Monthly!$B$27 -> 8025738.8 | D32: =Agg_Monthly!$C$27 -> 5148809.1 | E32: =C32-D32 -> 2876929.7 | F32: =IFERROR(E32/C32,0) -> 0.35846291 | G32: =Agg_Monthly!$D$27 -> 388064.05 | H32: =Agg_Opex!$B$27 -> 981858.42 | I32: =Agg_Opex!$C$27 -> 1007278 | J32: =G32+H32+I32 -> 2377200.5 | K32: =E32-G32-H32-I32 -> 499729.27 | L32: =IFERROR(K32/C32,0) -> 0.062265827 | M32: =IF(ROW()<43,C32,NA()) -> 8025738.8 | N32: =IF(ROW()>=43,C32,NA()) -> #N/A | O32: =IF(ROW()<43,K32,NA()) -> 499729.27 | P32: =IF(ROW()>=43,K32,NA()) -> #N/A | Q32: =IF($B32>2,SUM(C30:C32),"") -> 23712105
A33: 45808 | B33: 27 | C33: =Agg_Monthly!$B$28 -> 8104083.3 | D33: =Agg_Monthly!$C$28 -> 5218243 | E33: =C33-D33 -> 2885840.3 | F33: =IFERROR(E33/C33,0) -> 0.35609706 | G33: =Agg_Monthly!$D$28 -> 420029.69 | H33: =Agg_Opex!$B$28 -> 994265 | I33: =Agg_Opex!$C$28 -> 1086761 | J33: =G33+H33+I33 -> 2501055.7 | K33: =E33-G33-H33-I33 -> 384784.57 | L33: =IFERROR(K33/C33,0) -> 0.047480332 | M33: =IF(ROW()<43,C33,NA()) -> 8104083.3 | N33: =IF(ROW()>=43,C33,NA()) -> #N/A | O33: =IF(ROW()<43,K33,NA()) -> 384784.57 | P33: =IF(ROW()>=43,K33,NA()) -> #N/A | Q33: =IF($B33>2,SUM(C31:C33),"") -> 24692571
A34: 45838 | B34: 28 | C34: =Agg_Monthly!$B$29 -> 8892356.6 | D34: =Agg_Monthly!$C$29 -> 5699031.4 | E34: =C34-D34 -> 3193325.2 | F34: =IFERROR(E34/C34,0) -> 0.35910899 | G34: =Agg_Monthly!$D$29 -> 430236.66 | H34: =Agg_Opex!$B$29 -> 967356.5 | I34: =Agg_Opex!$C$29 -> 1021135 | J34: =G34+H34+I34 -> 2418728.2 | K34: =E34-G34-H34-I34 -> 774597.03 | L34: =IFERROR(K34/C34,0) -> 0.087108183 | M34: =IF(ROW()<43,C34,NA()) -> 8892356.6 | N34: =IF(ROW()>=43,C34,NA()) -> #N/A | O34: =IF(ROW()<43,K34,NA()) -> 774597.03 | P34: =IF(ROW()>=43,K34,NA()) -> #N/A | Q34: =IF($B34>2,SUM(C32:C34),"") -> 25022179
A35: 45869 | B35: 29 | C35: =Agg_Monthly!$B$30 -> 9582414.7 | D35: =Agg_Monthly!$C$30 -> 6221488.8 | E35: =C35-D35 -> 3360925.8 | F35: =IFERROR(E35/C35,0) -> 0.35073893 | G35: =Agg_Monthly!$D$30 -> 428566.03 | H35: =Agg_Opex!$B$30 -> 1022722.6 | I35: =Agg_Opex!$C$30 -> 1012458 | J35: =G35+H35+I35 -> 2463746.6 | K35: =E35-G35-H35-I35 -> 897179.23 | L35: =IFERROR(K35/C35,0) -> 0.093627678 | M35: =IF(ROW()<43,C35,NA()) -> 9582414.7 | N35: =IF(ROW()>=43,C35,NA()) -> #N/A | O35: =IF(ROW()<43,K35,NA()) -> 897179.23 | P35: =IF(ROW()>=43,K35,NA()) -> #N/A | Q35: =IF($B35>2,SUM(C33:C35),"") -> 26578855
A36: 45900 | B36: 30 | C36: =Agg_Monthly!$B$31 -> 9212797.5 | D36: =Agg_Monthly!$C$31 -> 5920960.6 | E36: =C36-D36 -> 3291836.9 | F36: =IFERROR(E36/C36,0) -> 0.35731133 | G36: =Agg_Monthly!$D$31 -> 420929.87 | H36: =Agg_Opex!$B$31 -> 990189.25 | I36: =Agg_Opex!$C$31 -> 1092399 | J36: =G36+H36+I36 -> 2503518.1 | K36: =E36-G36-H36-I36 -> 788318.78 | L36: =IFERROR(K36/C36,0) -> 0.085567796 | M36: =IF(ROW()<43,C36,NA()) -> 9212797.5 | N36: =IF(ROW()>=43,C36,NA()) -> #N/A | O36: =IF(ROW()<43,K36,NA()) -> 788318.78 | P36: =IF(ROW()>=43,K36,NA()) -> #N/A | Q36: =IF($B36>2,SUM(C34:C36),"") -> 27687569
A37: 45930 | B37: 31 | C37: =Agg_Monthly!$B$32 -> 10052104 | D37: =Agg_Monthly!$C$32 -> 6447760.5 | E37: =C37-D37 -> 3604343 | F37: =IFERROR(E37/C37,0) -> 0.35856605 | G37: =Agg_Monthly!$D$32 -> 515902.88 | H37: =Agg_Opex!$B$32 -> 1107650 | I37: =Agg_Opex!$C$32 -> 1021922 | J37: =G37+H37+I37 -> 2645474.9 | K37: =E37-G37-H37-I37 -> 958868.17 | L37: =IFERROR(K37/C37,0) -> 0.095389802 | M37: =IF(ROW()<43,C37,NA()) -> 10052104 | N37: =IF(ROW()>=43,C37,NA()) -> #N/A | O37: =IF(ROW()<43,K37,NA()) -> 958868.17 | P37: =IF(ROW()>=43,K37,NA()) -> #N/A | Q37: =IF($B37>2,SUM(C35:C37),"") -> 28847316
A38: 45961 | B38: 32 | C38: =Agg_Monthly!$B$33 -> 9788962 | D38: =Agg_Monthly!$C$33 -> 6404483.1 | E38: =C38-D38 -> 3384478.9 | F38: =IFERROR(E38/C38,0) -> 0.34574441 | G38: =Agg_Monthly!$D$33 -> 486439.25 | H38: =Agg_Opex!$B$33 -> 1016706.2 | I38: =Agg_Opex!$C$33 -> 1188028 | J38: =G38+H38+I38 -> 2691173.5 | K38: =E38-G38-H38-I38 -> 693305.44 | L38: =IFERROR(K38/C38,0) -> 0.070825225 | M38: =IF(ROW()<43,C38,NA()) -> 9788962 | N38: =IF(ROW()>=43,C38,NA()) -> #N/A | O38: =IF(ROW()<43,K38,NA()) -> 693305.44 | P38: =IF(ROW()>=43,K38,NA()) -> #N/A | Q38: =IF($B38>2,SUM(C36:C38),"") -> 29053863
A39: 45991 | B39: 33 | C39: =Agg_Monthly!$B$34 -> 10925888 | D39: =Agg_Monthly!$C$34 -> 7271478.3 | E39: =C39-D39 -> 3654409.9 | F39: =IFERROR(E39/C39,0) -> 0.33447257 | G39: =Agg_Monthly!$D$34 -> 506200.3 | H39: =Agg_Opex!$B$34 -> 1023592.4 | I39: =Agg_Opex!$C$34 -> 1142771 | J39: =G39+H39+I39 -> 2672563.7 | K39: =E39-G39-H39-I39 -> 981846.23 | L39: =IFERROR(K39/C39,0) -> 0.089864202 | M39: =IF(ROW()<43,C39,NA()) -> 10925888 | N39: =IF(ROW()>=43,C39,NA()) -> #N/A | O39: =IF(ROW()<43,K39,NA()) -> 981846.23 | P39: =IF(ROW()>=43,K39,NA()) -> #N/A | Q39: =IF($B39>2,SUM(C37:C39),"") -> 30766954
A40: 46022 | B40: 34 | C40: =Agg_Monthly!$B$35 -> 12006272 | D40: =Agg_Monthly!$C$35 -> 7953390 | E40: =C40-D40 -> 4052881.6 | F40: =IFERROR(E40/C40,0) -> 0.33756371 | G40: =Agg_Monthly!$D$35 -> 572392 | H40: =Agg_Opex!$B$35 -> 1061868.3 | I40: =Agg_Opex!$C$35 -> 1167716 | J40: =G40+H40+I40 -> 2801976.3 | K40: =E40-G40-H40-I40 -> 1250905.3 | L40: =IFERROR(K40/C40,0) -> 0.10418765 | M40: =IF(ROW()<43,C40,NA()) -> 12006272 | N40: =IF(ROW()>=43,C40,NA()) -> #N/A | O40: =IF(ROW()<43,K40,NA()) -> 1250905.3 | P40: =IF(ROW()>=43,K40,NA()) -> #N/A | Q40: =IF($B40>2,SUM(C38:C40),"") -> 32721122
A41: 46053 | B41: 35 | C41: =Agg_Monthly!$B$36 -> 8179645 | D41: =Agg_Monthly!$C$36 -> 5199996.2 | E41: =C41-D41 -> 2979648.7 | F41: =IFERROR(E41/C41,0) -> 0.36427605 | G41: =Agg_Monthly!$D$36 -> 405348.32 | H41: =Agg_Opex!$B$36 -> 1059106.2 | I41: =Agg_Opex!$C$36 -> 1079077 | J41: =G41+H41+I41 -> 2543531.5 | K41: =E41-G41-H41-I41 -> 436117.24 | L41: =IFERROR(K41/C41,0) -> 0.053317381 | M41: =IF(ROW()<43,C41,NA()) -> 8179645 | N41: =IF(ROW()>=43,C41,NA()) -> #N/A | O41: =IF(ROW()<43,K41,NA()) -> 436117.24 | P41: =IF(ROW()>=43,K41,NA()) -> #N/A | Q41: =IF($B41>2,SUM(C39:C41),"") -> 31111805
A42: 46081 | B42: 36 | C42: =Agg_Monthly!$B$37 -> 8640981.1 | D42: =Agg_Monthly!$C$37 -> 5587282.5 | E42: =C42-D42 -> 3053698.6 | F42: =IFERROR(E42/C42,0) -> 0.35339721 | G42: =Agg_Monthly!$D$37 -> 397928.15 | H42: =Agg_Opex!$B$37 -> 1070745.4 | I42: =Agg_Opex!$C$37 -> 1074950 | J42: =G42+H42+I42 -> 2543623.6 | K42: =E42-G42-H42-I42 -> 510075.03 | L42: =IFERROR(K42/C42,0) -> 0.059029758 | M42: =IF(ROW()<43,C42,NA()) -> 8640981.1 | N42: =IF(ROW()>=43,C42,NA()) -> #N/A | O42: =IF(ROW()<43,K42,NA()) -> 510075.03 | P42: =IF(ROW()>=43,K42,NA()) -> #N/A | Q42: =IF($B42>2,SUM(C40:C42),"") -> 28826898
A43: 46112 | B43: 37 | C43: ='Forecast Engine'!$E$11 -> 9289969.8 | D43: ='Forecast Engine'!$F$11 -> 6125122.1 | E43: =C43-D43 -> 3164847.7 | F43: =IFERROR(E43/C43,0) -> 0.34067363 | G43: ='Forecast Engine'!$G$11 -> 1300595.8 | H43: ='Forecast Engine'!$H$11 -> 1029957.7 | I43: ='Forecast Engine'!$I$11 -> 1092512.1 | J43: =G43+H43+I43 -> 3423065.6 | K43: =E43-G43-H43-I43 -> -258217.82 | L43: =IFERROR(K43/C43,0) -> -0.027795335 | M43: =IF(ROW()<43,C43,NA()) -> #N/A | N43: =IF(ROW()>=43,C43,NA()) -> 9289969.8 | O43: =IF(ROW()<43,K43,NA()) -> #N/A | P43: =IF(ROW()>=43,K43,NA()) -> -258217.82 | Q43: =SUM(C41:C43) -> 26110596
...

Sheet Forecast Engine
A1: Forecast Engine (12 months)
A4: Scenario | B4: =Inputs!$B$4 -> Downside | C4: This sheet produces the forecast inputs used by Model_PnL. Baseline: FORECAST() using 36 months of actual revenue. Scenario overlay: Active assumptions from Inputs. | H4: Base GM (last 12m) | I4: =AVERAGE(Model_PnL!$F$31:$F$42) -> 0.35267363
A5: Revenue Uplift | B5: =Inputs!$E$12 -> -0.06 | H5: Avg Payroll (last 12m) | I5: =AVERAGE(Model_PnL!$H$31:$H$42) -> 1022587.6
A6: GM Shift (bps) | B6: =Inputs!$E$13 -> -120 | H6: Avg Other Opex (last 12m) | I6: =AVERAGE(Model_PnL!$I$31:$I$42) -> 1084694.3
A7: Marketing % | B7: =Inputs!$E$14 -> 0.14
A8: Opex Growth (annual) | B8: =Inputs!$E$15 -> 0.09
A10: Month | B10: t | C10: Baseline Revenue | D10: Uplift | E10: Scenario Revenue | F10: COGS | G10: Marketing | H10: Payroll | I10: Other Opex | J10: EBITDA | K10: GM % | L10: EBITDA %
A11: 46112 | B11: 37 | C11: =FORECAST(B11,Model_PnL!$C$7:$C$42,Model_PnL!$B$7:$B$42) -> 9882946.6 | D11: =$B$5 -> -0.06 | E11: =C11*(1+$B$5) -> 9289969.8 | F11: =E11*(1-K11) -> 6125122.1 | G11: =E11*$B$7 -> 1300595.8 | H11: =$I$5*(1+$B$8)^((B11-36)/12) -> 1029957.7 | I11: =$I$6*(1+$B$8)^((B11-36)/12) -> 1092512.1 | J11: =E11-F11-G11-H11-I11 -> -258217.82 | K11: =$I$4 + $B$6/10000 -> 0.34067363 | L11: =IFERROR(J11/E11,0) -> -0.027795335
A12: 46142 | B12: 38 | C12: =FORECAST(B12,Model_PnL!$C$7:$C$42,Model_PnL!$B$7:$B$42) -> 9986423.1 | D12: =$B$5 -> -0.06 | E12: =C12*(1+$B$5) -> 9387237.7 | F12: =E12*(1-K12) -> 6189253.4 | G12: =E12*$B$7 -> 1314213.3 | H12: =$I$5*(1+$B$8)^((B12-36)/12) -> 1037381 | I12: =$I$6*(1+$B$8)^((B12-36)/12) -> 1100386.2 | J12: =E12-F12-G12-H12-I12 -> -253996.04 | K12: =$I$4 + $B$6/10000 -> 0.34067363 | L12: =IFERROR(J12/E12,0) -> -0.027057591
A13: 46173 | B13: 39 | C13: =FORECAST(B13,Model_PnL!$C$7:$C$42,Model_PnL!$B$7:$B$42) -> 10089900 | D13: =$B$5 -> -0.06 | E13: =C13*(1+$B$5) -> 9484505.7 | F13: =E13*(1-K13) -> 6253384.7 | G13: =E13*$B$7 -> 1327830.8 | H13: =$I$5*(1+$B$8)^((B13-36)/12) -> 1044857.7 | I13: =$I$6*(1+$B$8)^((B13-36)/12) -> 1108317 | J13: =E13-F13-G13-H13-I13 -> -249884.5 | K13: =$I$4 + $B$6/10000 -> 0.34067363 | L13: =IFERROR(J13/E13,0) -> -0.026346603
A14: 46203 | B14: 40 | C14: =FORECAST(B14,Model_PnL!$C$7:$C$42,Model_PnL!$B$7:$B$42) -> 10193376 | D14: =$B$5 -> -0.06 | E14: =C14*(1+$B$5) -> 9581773.6 | F14: =E14*(1-K14) -> 6317516 | G14: =E14*$B$7 -> 1341448.3 | H14: =$I$5*(1+$B$8)^((B14-36)/12) -> 1052388.3 | I14: =$I$6*(1+$B$8)^((B14-36)/12) -> 1116305 | J14: =E14-F14-G14-H14-I14 -> -245884.02 | K14: =$I$4 + $B$6/10000 -> 0.34067363 | L14: =IFERROR(J14/E14,0) -> -0.025661639
A15: 46234 | B15: 41 | C15: =FORECAST(B15,Model_PnL!$C$7:$C$42,Model_PnL!$B$7:$B$42) -> 10296853 | D15: =$B$5 -> -0.06 | E15: =C15*(1+$B$5) -> 9679041.6 | F15: =E15*(1-K15) -> 6381647.3 | G15: =E15*$B$7 -> 1355065.8 | H15: =$I$5*(1+$B$8)^((B15-36)/12) -> 1059973.2 | I15: =$I$6*(1+$B$8)^((B15-36)/12) -> 1124350.6 | J15: =E15-F15-G15-H15-I15 -> -241995.38 | K15: =$I$4 + $B$6/10000 -> 0.34067363 | L15: =IFERROR(J15/E15,0) -> -0.025001998
A16: 46265 | B16: 42 | C16: =FORECAST(B16,Model_PnL!$C$7:$C$42,Model_PnL!$B$7:$B$42) -> 10400329 | D16: =$B$5 -> -0.06 | E16: =C16*(1+$B$5) -> 9776309.5 | F16: =E16*(1-K16) -> 6445778.7 | G16: =E16*$B$7 -> 1368683.3 | H16: =$I$5*(1+$B$8)^((B16-36)/12) -> 1067612.8 | I16: =$I$6*(1+$B$8)^((B16-36)/12) -> 1132454.1 | J16: =E16-F16-G16-H16-I16 -> -238219.4 | K16: =$I$4 + $B$6/10000 -> 0.34067363 | L16: =IFERROR(J16/E16,0) -> -0.024367006
A17: 46295 | B17: 43 | C17: =FORECAST(B17,Model_PnL!$C$7:$C$42,Model_PnL!$B$7:$B$42) -> 10503806 | D17: =$B$5 -> -0.06 | E17: =C17*(1+$B$5) -> 9873577.5 | F17: =E17*(1-K17) -> 6509910 | G17: =E17*$B$7 -> 1382300.8 | H17: =$I$5*(1+$B$8)^((B17-36)/12) -> 1075307.4 | I17: =$I$6*(1+$B$8)^((B17-36)/12) -> 1140616.1 | J17: =E17-F17-G17-H17-I17 -> -234556.88 | K17: =$I$4 + $B$6/10000 -> 0.34067363 | L17: =IFERROR(J17/E17,0) -> -0.023756017
A18: 46326 | B18: 44 | C18: =FORECAST(B18,Model_PnL!$C$7:$C$42,Model_PnL!$B$7:$B$42) -> 10607282 | D18: =$B$5 -> -0.06 | E18: =C18*(1+$B$5) -> 9970845.4 | F18: =E18*(1-K18) -> 6574041.3 | G18: =E18*$B$7 -> 1395918.4 | H18: =$I$5*(1+$B$8)^((B18-36)/12) -> 1083057.5 | I18: =$I$6*(1+$B$8)^((B18-36)/12) -> 1148836.9 | J18: =E18-F18-G18-H18-I18 -> -231008.64 | K18: =$I$4 + $B$6/10000 -> 0.34067363 | L18: =IFERROR(J18/E18,0) -> -0.023168411
A19: 46356 | B19: 45 | C19: =FORECAST(B19,Model_PnL!$C$7:$C$42,Model_PnL!$B$7:$B$42) -> 10710759 | D19: =$B$5 -> -0.06 | E19: =C19*(1+$B$5) -> 10068113 | F19: =E19*(1-K19) -> 6638172.6 | G19: =E19*$B$7 -> 1409535.9 | H19: =$I$5*(1+$B$8)^((B19-36)/12) -> 1090863.5 | I19: =$I$6*(1+$B$8)^((B19-36)/12) -> 1157116.9 | J19: =E19-F19-G19-H19-I19 -> -227575.52 | K19: =$I$4 + $B$6/10000 -> 0.34067363 | L19: =IFERROR(J19/E19,0) -> -0.022603591
A20: 46387 | B20: 46 | C20: =FORECAST(B20,Model_PnL!$C$7:$C$42,Model_PnL!$B$7:$B$42) -> 10814235 | D20: =$B$5 -> -0.06 | E20: =C20*(1+$B$5) -> 10165381 | F20: =E20*(1-K20) -> 6702303.9 | G20: =E20*$B$7 -> 1423153.4 | H20: =$I$5*(1+$B$8)^((B20-36)/12) -> 1098725.7 | I20: =$I$6*(1+$B$8)^((B20-36)/12) -> 1165456.6 | J20: =E20-F20-G20-H20-I20 -> -224258.33 | K20: =$I$4 + $B$6/10000 -> 0.34067363 | L20: =IFERROR(J20/E20,0) -> -0.022060985
A21: 46418 | B21: 47 | C21: =FORECAST(B21,Model_PnL!$C$7:$C$42,Model_PnL!$B$7:$B$42) -> 10917712 | D21: =$B$5 -> -0.06 | E21: =C21*(1+$B$5) -> 10262649 | F21: =E21*(1-K21) -> 6766435.3 | G21: =E21*$B$7 -> 1436770.9 | H21: =$I$5*(1+$B$8)^((B21-36)/12) -> 1106644.5 | I21: =$I$6*(1+$B$8)^((B21-36)/12) -> 1173856.5 | J21: =E21-F21-G21-H21-I21 -> -221057.91 | K21: =$I$4 + $B$6/10000 -> 0.34067363 | L21: =IFERROR(J21/E21,0) -> -0.021540043
A22: 46446 | B22: 48 | C22: =FORECAST(B22,Model_PnL!$C$7:$C$42,Model_PnL!$B$7:$B$42) -> 11021189 | D22: =$B$5 -> -0.06 | E22: =C22*(1+$B$5) -> 10359917 | F22: =E22*(1-K22) -> 6830566.6 | G22: =E22*$B$7 -> 1450388.4 | H22: =$I$5*(1+$B$8)^((B22-36)/12) -> 1114620.5 | I22: =$I$6*(1+$B$8)^((B22-36)/12) -> 1182316.8 | J22: =E22-F22-G22-H22-I22 -> -217975.11 | K22: =$I$4 + $B$6/10000 -> 0.34067363 | L22: =IFERROR(J22/E22,0) -> -0.021040236

Sheet Raw_Sales
A1: Date | B1: Month | C1: Region | D1: Product | E1: Channel | F1: Units | G1: Unit Price | H1: Discount % | I1: Return % | J1: Unit COGS | K1: Orders | L1: New Customers | M1: CAC | N1: Gross Revenue | O1: Discounts | P1: Returns | Q1: Net Revenue | R1: COGS | S1: Gross Profit | T1: Marketing Spend
A2: 45016 | B2: 2023-03 | C2: North America | D2: Core | E2: Online DTC | F2: 6104 | G2: 119.3 | H2: 0.057892767 | I2: 0.055792128 | J2: 71.61 | K2: 4319 | L2: 1791 | M2: 29.3 | N2: 728207.2 | O2: 42157.93 | P2: 38276.149 | Q2: 647773.12 | R2: 437107.44 | S2: 210665.68 | T2: 52476.3
A3: 45016 | B3: 2023-03 | C3: North America | D3: Core | E3: Marketplace | F3: 3136 | G3: 113.48 | H3: 0.064170717 | I3: 0.034126233 | J3: 68.82 | K3: 2565 | L3: 748 | M3: 14.72 | N3: 355873.28 | O3: 22836.643 | P3: 11365.286 | Q3: 321671.35 | R3: 215819.52 | S3: 105851.83 | T3: 11010.56
A4: 45016 | B4: 2023-03 | C4: North America | D4: Core | E4: Wholesale | F4: 2408 | G4: 102.01 | H4: 0.038645342 | I4: 0.020337641 | J4: 67.01 | K4: 193 | L4: 11 | M4: 4.51 | N4: 245640.08 | O4: 9492.8449 | P4: 4802.6777 | Q4: 231344.56 | R4: 161360.08 | S4: 69984.477 | T4: 49.61
A5: 45016 | B5: 2023-03 | C5: North America | D5: Premium | E5: Online DTC | F5: 2902 | G5: 216.7 | H5: 0.057374756 | I5: 0.033982934 | J5: 126.67 | K5: 1909 | L5: 742 | M5: 31.92 | N5: 628863.4 | O5: 36080.884 | P5: 20144.489 | Q5: 572638.03 | R5: 367596.34 | S5: 205041.69 | T5: 23684.64
A6: 45016 | B6: 2023-03 | C6: North America | D6: Premium | E6: Marketplace | F6: 1069 | G6: 207.88 | H6: 0.063544453 | I6: 0.040077209 | J6: 120.71 | K6: 920 | L6: 256 | M6: 20.39 | N6: 222223.72 | O6: 14121.085 | P6: 8340.1729 | Q6: 199762.46 | R6: 129038.99 | S6: 70723.472 | T6: 5219.84
A7: 45016 | B7: 2023-03 | C7: North America | D7: Premium | E7: Wholesale | F7: 1067 | G7: 173.73 | H7: 0.035680935 | I7: 0.017696806 | J7: 123.81 | K7: 89 | L7: 5 | M7: 5.31 | N7: 185369.91 | O7: 6614.1717 | P7: 3163.4056 | Q7: 175592.33 | R7: 132105.27 | S7: 43487.063 | T7: 26.55
A8: 45016 | B8: 2023-03 | C8: North America | D8: Accessories | E8: Online DTC | F8: 1657 | G8: 44.24 | H8: 0.065505087 | I8: 0.050309995 | J8: 22.61 | K8: 1158 | L8: 430 | M8: 27.17 | N8: 73305.68 | O8: 4801.8949 | P8: 3446.4251 | Q8: 65057.36 | R8: 37464.77 | S8: 27592.59 | T8: 11683.1
A9: 45016 | B9: 2023-03 | C9: North America | D9: Accessories | E9: Marketplace | F9: 978 | G9: 41.79 | H9: 0.087493604 | I9: 0.043404975 | J9: 21.21 | K9: 826 | L9: 262 | M9: 20.63 | N9: 40870.62 | O9: 3575.9178 | P9: 1618.7756 | Q9: 35675.927 | R9: 20743.38 | S9: 14932.547 | T9: 5405.06
A10: 45016 | B10: 2023-03 | C10: North America | D10: Accessories | E10: Wholesale | F10: 1056 | G10: 37.23 | H10: 0.036129281 | I10: 0.021806978 | J10: 23.02 | K10: 88 | L10: 6 | M10: 4.97 | N10: 39314.88 | O10: 1420.4184 | P10: 826.36369 | Q10: 37068.098 | R10: 24309.12 | S10: 12758.978 | T10: 29.82
A11: 45016 | B11: 2023-03 | C11: Europe | D11: Core | E11: Online DTC | F11: 5806 | G11: 129.88 | H11: 0.057308934 | I11: 0.040917608 | J11: 68.46 | K11: 3585 | L11: 1429 | M11: 30.73 | N11: 754083.28 | O11: 43215.709 | P11: 29087 | Q11: 681780.57 | R11: 397478.76 | S11: 284301.81 | T11: 43913.17
A12: 45016 | B12: 2023-03 | C12: Europe | D12: Core | E12: Marketplace | F12: 2123 | G12: 119.36 | H12: 0.08322628 | I12: 0.073731032 | J12: 73.52 | K12: 1874 | L12: 545 | M12: 16.28 | N12: 253401.28 | O12: 21089.646 | P12: 17128.576 | Q12: 215183.06 | R12: 156082.96 | S12: 59100.098 | T12: 8872.6
A13: 45016 | B13: 2023-03 | C13: Europe | D13: Core | E13: Wholesale | F13: 1747 | G13: 104.41 | H13: 0.038034027 | I13: 0.018039459 | J13: 69.6 | K13: 146 | L13: 9 | M13: 5.27 | N13: 182404.27 | O13: 6937.569 | P13: 3165.3244 | Q13: 172301.38 | R13: 121591.2 | S13: 50710.177 | T13: 47.43
... A1297: 46081 | B1297: 2026-02 | C1297: LATAM | D1297: Accessories | E1297: Wholesale | F1297: 257 | G1297: 34.38 | H1297: 0.039620181 | I1297: 0.019607058 | J1297: 23.22 | K1297: 23 | L1297: 1 | M1297: 5.01 | N1297: 8835.66 | O1297: 350.07045 | P1297: 166.37745 | Q1297: 8319.2121 | R1297: 5967.54 | S1297: 2351.6721 | T1297: 5.01

Sheet Raw_Opex
A1: Date | B1: Month | C1: Department | D1: Headcount | E1: Avg Salary (Annual) | F1: Payroll | G1: Other Opex | H1: Total Opex
A2: 45016 | B2: 2023-03 | C2: Sales & Marketing | D2: 38 | E2: 96489 | F2: 305548.5 | G2: 424059 | H2: 729607.5
A3: 45016 | B3: 2023-03 | C3: R&D | D3: 25 | E3: 127166 | F3: 264929.17 | G3: 182789 | H3: 447718.17
A4: 45016 | B4: 2023-03 | C4: G&A | D4: 14 | E4: 90240 | F4: 105280 | G4: 237730 | H4: 343010
A5: 45016 | B5: 2023-03 | C5: Support | D5: 22 | E5: 65003 | F5: 119172.17 | G5: 137820 | H5: 256992.17
A6: 45046 | B6: 2023-04 | C6: Sales & Marketing | D6: 40 | E6: 95548 | F6: 318493.33 | G6: 449847 | H6: 768340.33
A7: 45046 | B7: 2023-04 | C7: R&D | D7: 26 | E7: 127298 | F7: 275812.33 | G7: 186189 | H7: 462001.33
A8: 45046 | B8: 2023-04 | C8: G&A | D8: 14 | E8: 90207 | F8: 105241.5 | G8: 240748 | H8: 345989.5
A9: 45046 | B9: 2023-04 | C9: Support | D9: 22 | E9: 65123 | F9: 119392.17 | G9: 134714 | H9: 254106.17
A10: 45077 | B10: 2023-05 | C10: Sales & Marketing | D10: 40 | E10: 93685 | F10: 312283.33 | G10: 407836 | H10: 720119.33
A11: 45077 | B11: 2023-05 | C11: R&D | D11: 27 | E11: 126220 | F11: 283995 | G11: 180209 | H11: 464204
A12: 45077 | B12: 2023-05 | C12: G&A | D12: 14 | E12: 90694 | F12: 105809.67 | G12: 229597 | H12: 335406.67
A13: 45077 | B13: 2023-05 | C13: Support | D13: 22 | E13: 66909 | F13: 122666.5 | G13: 133279 | H13: 255945.5
... A145: 46081 | B145: 2026-02 | C145: Support | D145: 26 | E145: 72687 | F145: 157488.5 | G145: 149911 | H145: 307399.5

Sheet Agg_Monthly
A1: Month | B1: Net Revenue | C1: COGS | D1: Marketing Spend | E1: Orders | F1: New Customers | G1: Gross Profit
A2: 45016 | B2: 6111106.7 | C2: 4028660.1 | D2: 287718.37 | E2: 31898 | F2: 10961 | G2: 2082446.6
A3: 45046 | B3: 6112814.3 | C3: 4049039.1 | D3: 323051.33 | E3: 32492 | F3: 11257 | G3: 2063775.1
A4: 45077 | B4: 6464674.9 | C4: 4220475.6 | D4: 331177.31 | E4: 34012 | F4: 11793 | G4: 2244199.3
A5: 45107 | B5: 6892942.5 | C5: 4524380 | D5: 390841.65 | E5: 37753 | F5: 13243 | G5: 2368562.6
A6: 45138 | B6: 6958622.9 | C6: 4623110.5 | D6: 401729.77 | E6: 39319 | F6: 13229 | G6: 2335512.4
A7: 45169 | B7: 6349906.8 | C7: 4153524.3 | D7: 371589.65 | E7: 34286 | F7: 12050 | G7: 2196382.5
A8: 45199 | B8: 6791502.7 | C8: 4491153.4 | D8: 353431.32 | E8: 36063 | F8: 12487 | G8: 2300349.3
A9: 45230 | B9: 6747149 | C9: 4380190.7 | D9: 356364.25 | E9: 35708 | F9: 12450 | G9: 2366958.3
A10: 45260 | B10: 7870188.9 | C10: 5294709.9 | D10: 412347.22 | E10: 43811 | F10: 15077 | G10: 2575479
A11: 45291 | B11: 8601676.2 | C11: 5883293.6 | D11: 457007.23 | E11: 45942 | F11: 15743 | G11: 2718382.6
A12: 45322 | B12: 5938555.9 | C12: 3882425.4 | D12: 265644.7 | E12: 30437 | F12: 10390 | G12: 2056130.5
A13: 45351 | B13: 7017084.1 | C13: 4533151.7 | D13: 371175.7 | E13: 38773 | F13: 13192 | G13: 2483932.4
... A37: 46081 | B37: 8640981.1 | C37: 5587282.5 | D37: 397928.15 | E37: 44439 | F37: 15004 | G37: 3053698.6

Sheet Agg_Opex
A1: Month | B1: Payroll | C1: Other Opex | D1: Total Opex
A2: 45016 | B2: 794929.83 | C2: 982398 | D2: 1777327.8
A3: 45046 | B3: 818939.33 | C3: 1011498 | D3: 1830437.3
A4: 45077 | B4: 824754.5 | C4: 950921 | D4: 1775675.5
A5: 45107 | B5: 800499.17 | C5: 991353 | D5: 1791852.2
A6: 45138 | B6: 824750.67 | C6: 978587 | D6: 1803337.7
A7: 45169 | B7: 837845.75 | C7: 974751 | D7: 1812596.8
A8: 45199 | B8: 845206.75 | C8: 1099285 | D8: 1944491.8
A9: 45230 | B9: 830136.33 | C9: 1013925 | D9: 1844061.3
A10: 45260 | B10: 867556.83 | C10: 1158992 | D10: 2026548.8
A11: 45291 | B11: 855319.33 | C11: 1124583 | D11: 1979902.3
A12: 45322 | B12: 870086.92 | C12: 1003694 | D12: 1873780.9
A13: 45351 | B13: 887942.67 | C13: 990879 | D13: 1878821.7
... A37: 46081 | B37: 1070745.4 | C37: 1074950 | D37: 2145695.4

Sheet README
A1: How to use this dashboard
A4: 1) Start on the Dashboard tab.
A5: 2) Go to Inputs and change the Scenario (Base/Upside/Downside) or adjust levers in the Active column.
A6: 3) Forecast and KPIs update automatically via formulas (no macros).
A7: 4) Raw_Sales and Raw_Opex contain row-level drivers (price, discounts, CAC, headcount) with derived calculations.
A8: 5) Model_PnL aggregates to monthly financial statements and KPIs via SUMIFS.
A9: 6) Forecast uses FORECAST() baseline + scenario overlays for revenue, margin, marketing %, and opex growth.
A11: Design notes
A12: • Blue text: adjustable inputs. Green text: links across sheets. Purple text: logic. Black: formulas/outputs.
A13: • All figures are synthetic but designed to look like a realistic multi-region, multi-channel business.
